<?xml version="1.0" encoding="utf-8"?>
<!-- This URDF was automatically created by SolidWorks to URDF Exporter! Originally created by Stephen Brawner (brawner@gmail.com) 
     Commit Version: 1.6.0-1-g15f4949  Build Version: 1.6.7594.29634
     For more information, please see http://wiki.ros.org/sw_urdf_exporter -->
<robot
  name="spot">
  <link
    name="base_link">
    <inertial>
      <origin
        xyz="0.19335804264155 1.09028613075507 -0.489907846784819"
        rpy="0 0 0" />
      <mass
        value="5.803427008103" />
      <inertia
        ixx="25.6580174851382"
        ixy="-0.306773797748636"
        ixz="-6.09071647336008"
        iyy="29.5593069732356"
        iyz="-0.886998425802061"
        izz="13.2903933999679" />
    </inertial>
    <visual>
      <origin
        xyz="0 0 0"
        rpy="0 0 0" />
      <geometry>
        <mesh
          filename="package://spot/meshes/base_link.STL" />
      </geometry>
      <material
        name="">
        <color
          rgba="0.792156862745098 0.819607843137255 0.933333333333333 1" />
      </material>
    </visual>
    <collision>
      <origin
        xyz="0 0 0"
        rpy="0 0 0" />
      <geometry>
        <mesh
          filename="package://spot/meshes/base_link.STL" />
      </geometry>
    </collision>
  </link>
  <link
    name="front_left_shoulder">
    <inertial>
      <origin
        xyz="0.0570964685913076 -3.21964677141295E-14 3.11972669919669E-14"
        rpy="0 0 0" />
      <mass
        value="30.53429173528852" />
      <inertia
        ixx="0.00994019550549898"
        ixy="1.9298798670242E-17"
        ixz="-5.88721779659629E-17"
        iyy="0.0167510702037112"
        iyz="2.16840434497101E-19"
        izz="0.0167510702037112" />
    </inertial>
    <visual>
      <origin
        xyz="0 0 0"
        rpy="0 0 0" />
      <geometry>
        <mesh
          filename="package://spot/meshes/front_left_shoulder.STL" />
      </geometry>
      <material
        name="">
        <color
          rgba="0.792156862745098 0.819607843137255 0.933333333333333 1" />
      </material>
    </visual>
    <collision>
      <origin
        xyz="0 0 0"
        rpy="0 0 0" />
      <geometry>
        <mesh
          filename="package://spot/meshes/front_left_shoulder.STL" />
      </geometry>
    </collision>
  </link>
  <joint
    name="front_left_shoulder_joint"
    type="revolute">
    <origin
      xyz="-0.25046 0.7027 1.0765"
      rpy="0.15518 0.035316 0.39339" />
    <parent
      link="base_link" />
    <child
      link="front_left_shoulder" />
    <axis
      xyz="1 0 0" />
    <limit
      lower="-3"
      upper="3"
      effort="1.5"
      velocity="3" />
    <dynamics damping="10" friction="0.1"/>
  </joint>
  <link
    name="front_left_arm">
    <inertial>
      <origin
        xyz="0.304961947601789 -0.0086821124155978 -0.00290353140869312"
        rpy="0 0 0" />
      <mass
        value="90.28584073464102" />
      <inertia
        ixx="0.0392595554967885"
        ixy="-1.23772520010945E-15"
        ixz="7.05598773853566E-16"
        iyy="0.33098522161448"
        iyz="-4.85722573273506E-17"
        izz="0.360339880327651" />
    </inertial>
    <visual>
      <origin
        xyz="0 0 0"
        rpy="0 0 0" />
      <geometry>
        <mesh
          filename="package://spot/meshes/front_left_arm.STL" />
      </geometry>
      <material
        name="">
        <color
          rgba="0.792156862745098 0.819607843137255 0.933333333333333 1" />
      </material>
    </visual>
    <collision>
      <origin
        xyz="0 0 0"
        rpy="0 0 0" />
      <geometry>
        <mesh
          filename="package://spot/meshes/front_left_arm.STL" />
      </geometry>
    </collision>
  </link>
  <joint
    name="front_left_arm_joint"
    type="fixed">
    <origin
      xyz="0 0.01 0"
      rpy="-1.57079632679488 1.05158591852191 -1.57079632679488" />
    <parent
      link="front_left_shoulder" />
    <child
      link="front_left_arm" />
    <axis
      xyz="0 0 0" />
    <dynamics damping="10" friction="0.1"/>
  </joint>
  <link
    name="front_left_knee">
    <inertial>
      <origin
        xyz="-0.0129035314086925 -1.11022302462516E-16 5.55111512312578E-17"
        rpy="0 0 0" />
      <mass
        value="10.76714586764426" />
      <inertia
        ixx="0.00497009775274948"
        ixy="-2.81892564846231E-18"
        ixz="-9.48676900924816E-19"
        iyy="0.00395767043274496"
        iyz="5.42101086242752E-20"
        izz="0.00395767043274496" />
    </inertial>
    <visual>
      <origin
        xyz="0 0 0"
        rpy="0 0 0" />
      <geometry>
        <mesh
          filename="package://spot/meshes/front_left_knee.STL" />
      </geometry>
      <material
        name="">
        <color
          rgba="0.792156862745098 0.819607843137255 0.933333333333333 1" />
      </material>
    </visual>
    <collision>
      <origin
        xyz="0 0 0"
        rpy="0 0 0" />
      <geometry>
        <mesh
          filename="package://spot/meshes/front_left_knee.STL" />
      </geometry>
    </collision>
  </link>
  <joint
    name="front_left_knee_joint"
    type="revolute">
    <origin
      xyz="0.60496 -0.0086821 0"
      rpy="2.4751 -1.5708 0" />
    <parent
      link="front_left_arm" />
    <child
      link="front_left_knee" />
    <axis
      xyz="1 0 0" />
    <limit
      lower="-3"
      upper="3"
      effort="1.5"
      velocity="3" />
    <dynamics damping="10" friction="0.1"/>
  </joint>
  <link
    name="front_left_leg">
    <inertial>
      <origin
        xyz="0.403673940518981 -0.00689228859860869 -0.00290353140869268"
        rpy="0 0 0" />
      <mass
        value="10.4703696906554" />
      <inertia
        ixx="0.0439849528203729"
        ixy="3.963843142607E-16"
        ixz="1.33573707650214E-16"
        iyy="0.29378731962821"
        iyz="-4.85722573273506E-17"
        izz="0.318579210040317" />
    </inertial>
    <visual>
      <origin
        xyz="0 0 0"
        rpy="0 0 0" />
      <geometry>
        <mesh
          filename="package://spot/meshes/front_left_leg.STL" />
      </geometry>
      <material
        name="">
        <color
          rgba="0.792156862745098 0.819607843137255 0.933333333333333 1" />
      </material>
    </visual>
    <collision>
      <origin
        xyz="0 0 0"
        rpy="0 0 0" />
      <geometry>
        <mesh
          filename="package://spot/meshes/front_left_leg.STL" />
      </geometry>
    </collision>
  </link>
  <joint
    name="front_left_leg_joint"
    type="fixed">
    <origin
      xyz="0 0.0099999999999999 0"
      rpy="1.5707963267949 0.760424201805189 1.57079632679489" />
    <parent
      link="front_left_knee" />
    <child
      link="front_left_leg" />
    <axis
      xyz="0 0 0" />
    <dynamics damping="10" friction="0.1"/>
  </joint>
  <link
    name="rear_left_shoulder">
    <inertial>
      <origin
        xyz="0.0570964685913075 -1.33226762955019E-15 -1.15324416682938E-14"
        rpy="0 0 0" />
      <mass
        value="30.53429173528852" />
      <inertia
        ixx="0.00994019550549896"
        ixy="1.24683249835833E-18"
        ixz="-2.81892564846231E-18"
        iyy="0.0167510702037112"
        iyz="5.42101086242752E-20"
        izz="0.0167510702037112" />
    </inertial>
    <visual>
      <origin
        xyz="0 0 0"
        rpy="0 0 0" />
      <geometry>
        <mesh
          filename="package://spot/meshes/rear_left_shoulder.STL" />
      </geometry>
      <material
        name="">
        <color
          rgba="0.792156862745098 0.819607843137255 0.933333333333333 1" />
      </material>
    </visual>
    <collision>
      <origin
        xyz="0 0 0"
        rpy="0 0 0" />
      <geometry>
        <mesh
          filename="package://spot/meshes/rear_left_shoulder.STL" />
      </geometry>
    </collision>
  </link>
  <joint
    name="rear_left_shoulder_joint"
    type="fixed">
    <origin
      xyz="0.0051172 0.09004 1.1107"
      rpy="-1.5852 0.035316 0.39339" />
    <parent
      link="base_link" />
    <child
      link="rear_left_shoulder" />
    <axis
      xyz="1 0 0" />
    <limit
      lower="-3"
      upper="3"
      effort="1.5"
      velocity="3" />
    <dynamics damping="10" friction="0.1"/>
  </joint>
  <link
    name="rear_left_arm">
    <inertial>
      <origin
        xyz="0.290604864747068 -0.00342511803862211 -0.0029035314086929"
        rpy="0 0 0" />
      <mass
        value="90.28584073464103" />
      <inertia
        ixx="0.0392595554967885"
        ixy="-8.50691045384266E-14"
        ixz="6.72205346941013E-17"
        iyy="0.33098522161448"
        iyz="-6.93889390390723E-18"
        izz="0.360339880327652" />
    </inertial>
    <visual>
      <origin
        xyz="0 0 0"
        rpy="0 0 0" />
      <geometry>
        <mesh
          filename="package://spot/meshes/rear_left_arm.STL" />
      </geometry>
      <material
        name="">
        <color
          rgba="0.792156862745098 0.819607843137255 0.933333333333333 1" />
      </material>
    </visual>
    <collision>
      <origin
        xyz="0 0 0"
        rpy="0 0 0" />
      <geometry>
        <mesh
          filename="package://spot/meshes/rear_left_arm.STL" />
      </geometry>
    </collision>
  </link>
  <joint
    name="rear_left_arm_joint"
    type="continuous">
    <origin
      xyz="0 0.00999999999999979 0"
      rpy="1.5707963267949 0.349589114476772 1.5707963267949" />
    <parent
      link="rear_left_shoulder" />
    <child
      link="rear_left_arm" />
    <axis
      xyz="0 0 1" />
    <dynamics damping="10" friction="0.1"/>
  </joint>
  <link
    name="rear_left_knee">
    <inertial>
      <origin
        xyz="-0.0129035314086929 -7.79931674799172E-15 -2.33146835171283E-15"
        rpy="0 0 0" />
      <mass
        value="10.76714586764426" />
      <inertia
        ixx="0.00497009775274948"
        ixy="-6.50521303491303E-19"
        ixz="-2.31748214368777E-18"
        iyy="0.00395767043274496"
        iyz="0"
        izz="0.00395767043274496" />
    </inertial>
    <visual>
      <origin
        xyz="0 0 0"
        rpy="0 0 0" />
      <geometry>
        <mesh
          filename="package://spot/meshes/rear_left_knee.STL" />
      </geometry>
      <material
        name="">
        <color
          rgba="0.792156862745098 0.819607843137255 0.933333333333333 1" />
      </material>
    </visual>
    <collision>
      <origin
        xyz="0 0 0"
        rpy="0 0 0" />
      <geometry>
        <mesh
          filename="package://spot/meshes/rear_left_knee.STL" />
      </geometry>
    </collision>
  </link>
  <joint
    name="rear_left_knee_joint"
    type="fixed">
    <origin
      xyz="0.5906 -0.0034251 0"
      rpy="2.8471 -1.5708 0" />
    <parent
      link="rear_left_arm" />
    <child
      link="rear_left_knee" />
    <axis
      xyz="1 0 0" />
    <limit
      lower="-3"
      upper="3"
      effort="1.5"
      velocity="3" />
    <dynamics damping="10" friction="0.1"/>
  </joint>
  <link
    name="rear_left_leg">
    <inertial>
      <origin
        xyz="0.401664249497134 -0.00378716313216521 -0.00290353140869293"
        rpy="0 0 0" />
      <mass
        value="10.4703696906554" />
      <inertia
        ixx="0.043984952820373"
        ixy="-2.89972039435593E-13"
        ixz="2.60208521396521E-17"
        iyy="0.29378731962821"
        iyz="6.93889390390723E-18"
        izz="0.318579210040316" />
    </inertial>
    <visual>
      <origin
        xyz="0 0 0"
        rpy="0 0 0" />
      <geometry>
        <mesh
          filename="package://spot/meshes/rear_left_leg.STL" />
      </geometry>
      <material
        name="">
        <color
          rgba="0.792156862745098 0.819607843137255 0.933333333333333 1" />
      </material>
    </visual>
    <collision>
      <origin
        xyz="0 0 0"
        rpy="0 0 0" />
      <geometry>
        <mesh
          filename="package://spot/meshes/rear_left_leg.STL" />
      </geometry>
    </collision>
  </link>
  <joint
    name="rear_left_leg_joint"
    type="continuous">
    <origin
      xyz="0 0.01 0"
      rpy="1.5707963267949 0.388408901693264 1.5707963267949" />
    <parent
      link="rear_left_knee" />
    <child
      link="rear_left_leg" />
    <axis
      xyz="0 0 1" />
    <dynamics damping="10" friction="0.1"/>
  </joint>
  <link
    name="front_right_shoulder">
    <inertial>
      <origin
        xyz="0.0664137960412473 -1.11022302462516E-16 -8.88178419700125E-16"
        rpy="0 0 0" />
      <mass
        value="30.53429173528852" />
      <inertia
        ixx="0.00994019550549896"
        ixy="1.51788304147971E-18"
        ixz="6.23145198636044E-17"
        iyy="0.0167510702037112"
        iyz="3.25260651745651E-19"
        izz="0.0167510702037112" />
    </inertial>
    <visual>
      <origin
        xyz="0 0 0"
        rpy="0 0 0" />
      <geometry>
        <mesh
          filename="package://spot/meshes/front_right_shoulder.STL" />
      </geometry>
      <material
        name="">
        <color
          rgba="0.792156862745098 0.819607843137255 0.933333333333333 1" />
      </material>
    </visual>
    <collision>
      <origin
        xyz="0 0 0"
        rpy="0 0 0" />
      <geometry>
        <mesh
          filename="package://spot/meshes/front_right_shoulder.STL" />
      </geometry>
    </collision>
  </link>
  <joint
    name="front_right_shoulder_joint"
    type="revolute">
    <origin
      xyz="0.23397 0.90375 1.058"
      rpy="3.0811 0.035316 0.39339" />
    <parent
      link="base_link" />
    <child
      link="front_right_shoulder" />
    <axis
      xyz="1 0 0" />
    <limit
      lower="-3"
      upper="3"
      effort="1.5"
      velocity="3" />
    <dynamics damping="10" friction="0.1"/>
  </joint>
  <link
    name="front_right_arm">
    <inertial>
      <origin
        xyz="0.3 2.33146835171283E-15 4.44089209850063E-16"
        rpy="0 0 0" />
      <mass
        value="90.28584073464102" />
      <inertia
        ixx="0.0392595554967886"
        ixy="-2.07299455379228E-15"
        ixz="-3.57353036051222E-16"
        iyy="0.33098522161448"
        iyz="-4.85722573273506E-17"
        izz="0.360339880327652" />
    </inertial>
    <visual>
      <origin
        xyz="0 0 0"
        rpy="0 0 0" />
      <geometry>
        <mesh
          filename="package://spot/meshes/front_right_arm.STL" />
      </geometry>
      <material
        name="">
        <color
          rgba="0.792156862745098 0.819607843137255 0.933333333333333 1" />
      </material>
    </visual>
    <collision>
      <origin
        xyz="0 0 0"
        rpy="0 0 0" />
      <geometry>
        <mesh
          filename="package://spot/meshes/front_right_arm.STL" />
      </geometry>
    </collision>
  </link>
  <joint
    name="front_right_arm_joint"
    type="fixed">
    <origin
      xyz="0.126413796041247 0 0"
      rpy="-1.57079632679487 -1.24064228345131 1.57079632679487" />
    <parent
      link="front_right_shoulder" />
    <child
      link="front_right_arm" />
    <axis
      xyz="0 0 0" />
    <dynamics damping="10" friction="0.1"/>
  </joint>
  <link
    name="front_right_knee">
    <inertial>
      <origin
        xyz="-0.01 0 1.11022302462516E-16"
        rpy="0 0 0" />
      <mass
        value="10.76714586764426" />
      <inertia
        ixx="0.00497009775274948"
        ixy="-1.0842021724855E-18"
        ixz="-4.01154803819637E-18"
        iyy="0.00395767043274496"
        iyz="-1.0842021724855E-19"
        izz="0.00395767043274496" />
    </inertial>
    <visual>
      <origin
        xyz="0 0 0"
        rpy="0 0 0" />
      <geometry>
        <mesh
          filename="package://spot/meshes/front_right_knee.STL" />
      </geometry>
      <material
        name="">
        <color
          rgba="0.792156862745098 0.819607843137255 0.933333333333333 1" />
      </material>
    </visual>
    <collision>
      <origin
        xyz="0 0 0"
        rpy="0 0 0" />
      <geometry>
        <mesh
          filename="package://spot/meshes/front_right_knee.STL" />
      </geometry>
    </collision>
  </link>
  <joint
    name="front_right_knee_joint"
    type="revolute">
    <origin
      xyz="0.6 0 0"
      rpy="0.016482 1.5708 1.6092" />
    <parent
      link="front_right_arm" />
    <child
      link="front_right_knee" />
    <axis
      xyz="1 0 0" />
    <limit
      lower="-3"
      upper="3"
      effort="1.5"
      velocity="3" />
    <dynamics damping="10" friction="0.1" />
  </joint>
  <link
    name="front_right_leg">
    <inertial>
      <origin
        xyz="0.410912645299226 0.00999999773383875 1.11022302462516E-16"
        rpy="0 0 0" />
      <mass
        value="10.4703696906554" />
      <inertia
        ixx="0.0439849528203729"
        ixy="-2.30718222304915E-15"
        ixz="-6.67868538251071E-17"
        iyy="0.293787319628209"
        iyz="-3.46944695195361E-18"
        izz="0.318579210040316" />
    </inertial>
    <visual>
      <origin
        xyz="0 0 0"
        rpy="0 0 0" />
      <geometry>
        <mesh
          filename="package://spot/meshes/front_right_leg.STL" />
      </geometry>
      <material
        name="">
        <color
          rgba="0.792156862745098 0.819607843137255 0.933333333333333 1" />
      </material>
    </visual>
    <collision>
      <origin
        xyz="0 0 0"
        rpy="0 0 0" />
      <geometry>
        <mesh
          filename="package://spot/meshes/front_right_leg.STL" />
      </geometry>
    </collision>
  </link>
  <joint
    name="front_right_leg_joint"
    type="continuous">
    <origin
      xyz="0 0.01 0"
      rpy="-1.5708 1.5701 1.5708" />
    <parent
      link="front_right_knee" />
    <child
      link="front_right_leg" />
    <axis
      xyz="0 0 0" />
    <dynamics damping="10" friction="0.1"/>
  </joint>
  <link
    name="rear_right_shoulder">
    <inertial>
      <origin
        xyz="0.0677338767757805 -6.77236045021345E-15 -9.10382880192628E-15"
        rpy="0 0 0" />
      <mass
        value="30.53429173528852" />
      <inertia
        ixx="0.00994019550549896"
        ixy="1.29020058525775E-17"
        ixz="-2.51534904016637E-17"
        iyy="0.0167510702037112"
        iyz="-1.73472347597681E-18"
        izz="0.0167510702037112" />
    </inertial>
    <visual>
      <origin
        xyz="0 0 0"
        rpy="0 0 0" />
      <geometry>
        <mesh
          filename="package://spot/meshes/rear_right_shoulder.STL" />
      </geometry>
      <material
        name="">
        <color
          rgba="0.792156862745098 0.819607843137255 0.933333333333333 1" />
      </material>
    </visual>
    <collision>
      <origin
        xyz="0 0 0"
        rpy="0 0 0" />
      <geometry>
        <mesh
          filename="package://spot/meshes/rear_right_shoulder.STL" />
      </geometry>
    </collision>
  </link>
  <joint
    name="rear_right_shoulder_joint"
    type="fixed">
    <origin
      xyz="0.48833 0.29059 1.0922"
      rpy="-1.043 0.035316 0.39339" />
    <parent
      link="base_link" />
    <child
      link="rear_right_shoulder" />
    <axis
      xyz="1 0 0" />
    <limit
      lower="-3"
      upper="3"
      effort="1.5"
      velocity="3" />
    <dynamics damping="10" friction="0.1"/>
  </joint>
  <link
    name="rear_right_arm">
    <inertial>
      <origin
        xyz="0.299999999999992 -2.40363284831346E-14 -0.00205767353950237"
        rpy="0 0 0" />
      <mass
        value="90.28584073464101" />
      <inertia
        ixx="0.0392595554967885"
        ixy="-2.79550688153662E-15"
        ixz="1.25463875400023E-15"
        iyy="0.33098522161448"
        iyz="4.85722573273506E-17"
        izz="0.360339880327652" />
    </inertial>
    <visual>
      <origin
        xyz="0 0 0"
        rpy="0 0 0" />
      <geometry>
        <mesh
          filename="package://spot/meshes/rear_right_arm.STL" />
      </geometry>
      <material
        name="">
        <color
          rgba="0.792156862745098 0.819607843137255 0.933333333333333 1" />
      </material>
    </visual>
    <collision>
      <origin
        xyz="0 0 0"
        rpy="0 0 0" />
      <geometry>
        <mesh
          filename="package://spot/meshes/rear_right_arm.STL" />
      </geometry>
    </collision>
  </link>
  <joint
    name="rear_right_arm_joint"
    type="continuous">
    <origin
      xyz="0.125676203236276 0 0"
      rpy="-1.5707963267949 0.918489749936598 1.5707963267949" />
    <parent
      link="rear_right_shoulder" />
    <child
      link="rear_right_arm" />
    <axis
      xyz="0 0 1" />
    <dynamics damping="10" friction="0.1"/>
  </joint>
  <link
    name="rear_right_knee">
    <inertial>
      <origin
        xyz="0.0120576735395013 0 -5.55111512312578E-17"
        rpy="0 0 0" />
      <mass
        value="10.76714586764426" />
      <inertia
        ixx="0.00497009775274948"
        ixy="1.30104260698261E-18"
        ixz="-7.58941520739853E-19"
        iyy="0.00395767043274495"
        iyz="5.42101086242752E-19"
        izz="0.00395767043274495" />
    </inertial>
    <visual>
      <origin
        xyz="0 0 0"
        rpy="0 0 0" />
      <geometry>
        <mesh
          filename="package://spot/meshes/rear_right_knee.STL" />
      </geometry>
      <material
        name="">
        <color
          rgba="0.792156862745098 0.819607843137255 0.933333333333333 1" />
      </material>
    </visual>
    <collision>
      <origin
        xyz="0 0 0"
        rpy="0 0 0" />
      <geometry>
        <mesh
          filename="package://spot/meshes/rear_right_knee.STL" />
      </geometry>
    </collision>
  </link>
  <joint
    name="rear_right_knee_joint"
    type="fixed">
    <origin
      xyz="0.6 0 0"
      rpy="2.4536 1.5708 0" />
    <parent
      link="rear_right_arm" />
    <child
      link="rear_right_knee" />
    <axis
      xyz="1 0 0" />
    <limit
      lower="-3"
      upper="3"
      effort="1.5"
      velocity="3" />
    <dynamics damping="10" friction="0.1"/>
  </joint>
  <link
    name="rear_right_leg">
    <inertial>
      <origin
        xyz="0.403066666092815 0.00619152022192465 0.00205767353950193"
        rpy="0 0 0" />
      <mass
        value="10.4703696906554" />
      <inertia
        ixx="0.0439849528203728"
        ixy="9.01188845769951E-16"
        ixz="-5.5944832100252E-16"
        iyy="0.293787319628209"
        iyz="3.12250225675825E-17"
        izz="0.318579210040316" />
    </inertial>
    <visual>
      <origin
        xyz="0 0 0"
        rpy="0 0 0" />
      <geometry>
        <mesh
          filename="package://spot/meshes/rear_right_leg.STL" />
      </geometry>
      <material
        name="">
        <color
          rgba="0.792156862745098 0.819607843137255 0.933333333333333 1" />
      </material>
    </visual>
    <collision>
      <origin
        xyz="0 0 0"
        rpy="0 0 0" />
      <geometry>
        <mesh
          filename="package://spot/meshes/rear_right_leg.STL" />
      </geometry>
    </collision>
  </link>
  <joint
    name="rear_right_leg_joint"
    type="continuous">
    <origin
      xyz="0 0.0099999999999999 0"
      rpy="1.5707963267949 -0.667662389382688 1.5707963267949" />
    <parent
      link="rear_right_knee" />
    <child
      link="rear_right_leg" />
    <axis
      xyz="0 0 1" />
    <dynamics damping="10" friction="0.1"/>
  </joint>
    <!--Adding Dummy Link-->
  <link
    name="dummy_link">
  </link>
  <joint
    name="dummy_joint"
    type="fixed">
    <parent
      link="dummy_link" />
    <child
      link="base_link" />
    <dynamics damping="10" friction="0.1"/>
  </joint>
  <!--Adding Colors-->
  <gazebo reference="base_link">
    <material>Gazebo/Yellow</material>
  </gazebo>
  <gazebo reference="front_left_shoulder">
    <material>Gazebo/Black</material>
  </gazebo>
  <gazebo reference="front_right_shoulder">
    <material>Gazebo/Black</material>
  </gazebo>
  <gazebo reference="rear_left_shoulder">
    <material>Gazebo/Black</material>
  </gazebo>
  <gazebo reference="rear_right_shoulder">
    <material>Gazebo/Black</material>
  </gazebo>
    <gazebo reference="front_left_arm">
    <material>Gazebo/Yellow</material>
  </gazebo>
  <gazebo reference="front_right_arm">
    <material>Gazebo/Yellow</material>
  </gazebo>
  <gazebo reference="rear_left_arm">
    <material>Gazebo/Yellow</material>
  </gazebo>
  <gazebo reference="rear_right_arm">
    <material>Gazebo/Yellow</material>
  </gazebo>
  <gazebo reference="front_left_knee">
    <material>Gazebo/Black</material>
  </gazebo>
  <gazebo reference="front_right_knee">
    <material>Gazebo/Black</material>
  </gazebo>
  <gazebo reference="rear_left_knee">
    <material>Gazebo/Black</material>
  </gazebo>
  <gazebo reference="rear_right_knee">
    <material>Gazebo/Black</material>
  </gazebo>
    <gazebo reference="front_left_leg">
    <material>Gazebo/Yellow</material>
  </gazebo>
  <gazebo reference="front_right_leg">
    <material>Gazebo/Yellow</material>
  </gazebo>
  <gazebo reference="rear_left_leg">
    <material>Gazebo/Yellow</material>
  </gazebo>
  <gazebo reference="rear_right_leg">
    <material>Gazebo/Yellow</material>
  </gazebo>
  <!--Adding Transmissions-->
  <transmission name="transmission_front_left_shoulder_joint">
    <type>transmission_interface/SimpleTransmission</type>
    <joint name="front_left_shoulder_joint">
      <hardwareInterface>hardware_interface/VelocityJointInterface</hardwareInterface>
      <dynamics damping="10" friction="0.1"/>
  </joint>
    <actuator name="front_left_shoulder_joint_motor">
      <mechanicalReduction>1</mechanicalReduction>
      <hardwareInterface>hardware_interface/VelocityJointInterface</hardwareInterface>
    </actuator>
  </transmission>
  <transmission name="transmission_front_right_shoulder_joint">
    <type>transmission_interface/SimpleTransmission</type>
    <joint name="front_right_shoulder_joint">
      <hardwareInterface>hardware_interface/VelocityJointInterface</hardwareInterface>
      <dynamics damping="10" friction="0.1"/>
  </joint>
    <actuator name="front_right_shoulder_joint_motor">
      <mechanicalReduction>1</mechanicalReduction>
      <hardwareInterface>hardware_interface/VelocityJointInterface</hardwareInterface>
    </actuator>
  </transmission>
  <transmission name="transmission_rear_left_shoulder_joint">
    <type>transmission_interface/SimpleTransmission</type>
    <joint name="rear_left_shoulder_joint">
      <hardwareInterface>hardware_interface/VelocityJointInterface</hardwareInterface>
      <dynamics damping="10" friction="0.1"/>
  </joint>
    <actuator name="rear_left_shoulder_joint_motor">
      <mechanicalReduction>1</mechanicalReduction>
      <hardwareInterface>hardware_interface/VelocityJointInterface</hardwareInterface>
    </actuator>
  </transmission>
  <transmission name="transmission_rear_right_shoulder_joint">
    <type>transmission_interface/SimpleTransmission</type>
    <joint name="rear_right_shoulder_joint">
      <hardwareInterface>hardware_interface/VelocityJointInterface</hardwareInterface>
      <dynamics damping="10" friction="0.1"/>
  </joint>
    <actuator name="rear_right_shoulder_joint_motor">
      <mechanicalReduction>1</mechanicalReduction>
      <hardwareInterface>hardware_interface/VelocityJointInterface</hardwareInterface>
    </actuator>
  </transmission>
  <transmission name="transmission_front_left_arm_joint">
    <type>transmission_interface/SimpleTransmission</type>
    <joint name="front_left_arm_joint">
      <hardwareInterface>hardware_interface/VelocityJointInterface</hardwareInterface>
      <dynamics damping="10" friction="0.1"/>
  </joint>
    <actuator name="front_left_arm_joint_motor">
      <mechanicalReduction>1</mechanicalReduction>
      <hardwareInterface>hardware_interface/VelocityJointInterface</hardwareInterface>
    </actuator>
  </transmission>
  <transmission name="transmission_front_right_arm_joint">
    <type>transmission_interface/SimpleTransmission</type>
    <joint name="front_right_arm_joint">
      <hardwareInterface>hardware_interface/VelocityJointInterface</hardwareInterface>
      <dynamics damping="10" friction="0.1"/>
  </joint>
    <actuator name="front_right_arm_joint_motor">
      <mechanicalReduction>1</mechanicalReduction>
      <hardwareInterface>hardware_interface/VelocityJointInterface</hardwareInterface>
    </actuator>
  </transmission>
  <transmission name="transmission_rear_left_arm_joint">
    <type>transmission_interface/SimpleTransmission</type>
    <joint name="rear_left_arm_joint">
      <hardwareInterface>hardware_interface/VelocityJointInterface</hardwareInterface>
      <dynamics damping="10" friction="0.1"/>
  </joint>
    <actuator name="rear_left_arm_joint_motor">
      <mechanicalReduction>1</mechanicalReduction>
      <hardwareInterface>hardware_interface/VelocityJointInterface</hardwareInterface>
    </actuator>
  </transmission>
  <transmission name="transmission_rear_right_arm_joint">
    <type>transmission_interface/SimpleTransmission</type>
    <joint name="rear_right_arm_joint">
      <hardwareInterface>hardware_interface/VelocityJointInterface</hardwareInterface>
      <dynamics damping="10" friction="0.1"/>
  </joint>
    <actuator name="rear_right_arm_joint_motor">
      <mechanicalReduction>1</mechanicalReduction>
      <hardwareInterface>hardware_interface/VelocityJointInterface</hardwareInterface>
    </actuator>
  </transmission>
  <transmission name="transmission_front_left_knee_joint">
    <type>transmission_interface/SimpleTransmission</type>
    <joint name="front_left_knee_joint">
      <hardwareInterface>hardware_interface/VelocityJointInterface</hardwareInterface>
      <dynamics damping="10" friction="0.1"/>
  </joint>
    <actuator name="front_left_knee_joint_motor">
      <mechanicalReduction>1</mechanicalReduction>
      <hardwareInterface>hardware_interface/VelocityJointInterface</hardwareInterface>
    </actuator>
  </transmission>
  <transmission name="transmission_front_right_knee_joint">
    <type>transmission_interface/SimpleTransmission</type>
    <joint name="front_right_knee_joint">
      <hardwareInterface>hardware_interface/VelocityJointInterface</hardwareInterface>
      <dynamics damping="10" friction="0.1"/>
  </joint>
    <actuator name="front_right_knee_joint_motor">
      <mechanicalReduction>1</mechanicalReduction>
      <hardwareInterface>hardware_interface/VelocityJointInterface</hardwareInterface>
    </actuator>
  </transmission>
  <transmission name="transmission_rear_left_knee_joint">
    <type>transmission_interface/SimpleTransmission</type>
    <joint name="rear_left_knee_joint">
      <hardwareInterface>hardware_interface/VelocityJointInterface</hardwareInterface>
      <dynamics damping="10" friction="0.1"/>
  </joint>
    <actuator name="rear_left_knee_joint_motor">
      <mechanicalReduction>1</mechanicalReduction>
      <hardwareInterface>hardware_interface/VelocityJointInterface</hardwareInterface>
    </actuator>
  </transmission>
  <transmission name="transmission_rear_right_knee_joint">
    <type>transmission_interface/SimpleTransmission</type>
    <joint name="rear_right_knee_joint">
      <hardwareInterface>hardware_interface/VelocityJointInterface</hardwareInterface>
      <dynamics damping="10" friction="0.1"/>
  </joint>
    <actuator name="rear_right_knee_joint_motor">
      <mechanicalReduction>1</mechanicalReduction>
      <hardwareInterface>hardware_interface/VelocityJointInterface</hardwareInterface>
    </actuator>
  </transmission>
  <transmission name="transmission_front_left_leg_joint">
    <type>transmission_interface/SimpleTransmission</type>
    <joint name="front_left_leg_joint">
      <hardwareInterface>hardware_interface/VelocityJointInterface</hardwareInterface>
      <dynamics damping="10" friction="0.1"/>
  </joint>
    <actuator name="front_left_leg_joint_motor">
      <mechanicalReduction>1</mechanicalReduction>
      <hardwareInterface>hardware_interface/VelocityJointInterface</hardwareInterface>
    </actuator>
  </transmission>
  <transmission name="transmission_front_right_leg_joint">
    <type>transmission_interface/SimpleTransmission</type>
    <joint name="front_right_leg_joint">
      <hardwareInterface>hardware_interface/VelocityJointInterface</hardwareInterface>
      <dynamics damping="10" friction="0.1"/>
  </joint>
    <actuator name="front_right_leg_joint_motor">
      <mechanicalReduction>1</mechanicalReduction>
      <hardwareInterface>hardware_interface/VelocityJointInterface</hardwareInterface>
    </actuator>
  </transmission>
  <transmission name="transmission_rear_left_leg_joint">
    <type>transmission_interface/SimpleTransmission</type>
    <joint name="rear_left_leg_joint">
      <hardwareInterface>hardware_interface/VelocityJointInterface</hardwareInterface>
      <dynamics damping="10" friction="0.1"/>
  </joint>
    <actuator name="rear_left_leg_joint_motor">
      <mechanicalReduction>1</mechanicalReduction>
      <hardwareInterface>hardware_interface/VelocityJointInterface</hardwareInterface>
    </actuator>
  </transmission>
  <transmission name="transmission_rear_right_leg_joint">
    <type>transmission_interface/SimpleTransmission</type>
    <joint name="rear_right_leg_joint">
      <hardwareInterface>hardware_interface/VelocityJointInterface</hardwareInterface>
      <dynamics damping="10" friction="0.1"/>
  </joint>
    <actuator name="rear_right_leg_joint_motor">
      <mechanicalReduction>1</mechanicalReduction>
      <hardwareInterface>hardware_interface/VelocityJointInterface</hardwareInterface>
    </actuator>
  </transmission>
  <gazebo reference="base_link">
    <kp>1000000.0</kp>
    <kd>1.0</kd>
    <mu1>0.8</mu1>
    <mu2>0.8</mu2>
    <maxVel>0.0</maxVel>
    <minDepth>0.001</minDepth>
  </gazebo>
</robot>